<?xml version="1.0" ?>
<sdf version="1.8">
  <model name="turtlebot3_burger">
    <pose>0.0 0.0 0.0 0.0 0.0 0.0</pose>

    <link name="base_footprint"/>

    <link name="base_link">

      <inertial>
        <pose>-0.064 0 0.070 0 0 0</pose>
        <inertia>
          <ixx>1.9527e-02</ixx>
          <ixy>0</ixy>
          <ixz>0</ixz>
          <iyy>1.9527e-02</iyy>
          <iyz>0</iyz>
          <izz>1.9527e-02</izz>
        </inertia>
        <mass>8.2573504e-01</mass>
      </inertial>

      <collision name="base_collision">
        <pose>-0.032 0 0.070 0 0 0</pose>
        <geometry>
          <box>
            <size>0.14 0.14 0.14</size>
          </box>
        </geometry>
      </collision>

      <visual name="base_visual">
        <pose>-0.032 0 0 0 0 0</pose>
        <geometry>
          <mesh>
            <uri>model://turtlebot3_common/meshes/bases/burger_base.stl</uri>
            <scale>0.001 0.001 0.001</scale>
          </mesh>
        </geometry>
        <material>
          <ambient>0.3 0.3 0.3 1.0</ambient>
          <diffuse>0.3 0.3 0.3 1.0</diffuse>
        </material>
      </visual>
    </link>

    <link name="imu_link">
      <sensor name="tb3_imu" type="imu">
        <always_on>true</always_on>
        <update_rate>200</update_rate>
        <topic>imu</topic>
        <!-- Without this, gz stamps /imu with the default name
             "burger/imu_link/tb3_imu", which isn't in the URDF TF tree, so
             rtabmap can't resolve it and drops every IMU sample. imu_link is
             a real frame published by robot_state_publisher. -->
        <gz_frame_id>imu_link</gz_frame_id>
        <imu>
          <angular_velocity>
            <x>
              <noise type="gaussian">
                <mean>0.0</mean>
                <stddev>2e-4</stddev>
              </noise>
            </x>
            <y>
              <noise type="gaussian">
                <mean>0.0</mean>
                <stddev>2e-4</stddev>
              </noise>
            </y>
            <z>
              <noise type="gaussian">
                <mean>0.0</mean>
                <stddev>2e-4</stddev>
              </noise>
            </z>
          </angular_velocity>
          <linear_acceleration>
            <x>
              <noise type="gaussian">
                <mean>0.0</mean>
                <stddev>1.7e-2</stddev>
              </noise>
            </x>
            <y>
              <noise type="gaussian">
                <mean>0.0</mean>
                <stddev>1.7e-2</stddev>
              </noise>
            </y>
            <z>
              <noise type="gaussian">
                <mean>0.0</mean>
                <stddev>1.7e-2</stddev>
              </noise>
            </z>
          </linear_acceleration>
        </imu>
      </sensor>
    </link>

    <link name="base_scan">
      <inertial>
        <pose>-0.020 0 0.161 0 0 0</pose>
        <inertia>
          <ixx>0.0001</ixx>
          <ixy>0.000</ixy>
          <ixz>0.000</ixz>
          <iyy>0.0001</iyy>
          <iyz>0.000</iyz>
          <izz>0.0001</izz>
        </inertia>
        <mass>0.114</mass>
      </inertial>

      <collision name="lidar_sensor_collision">
        <pose>-0.020 0 0.161 0 0 0</pose>
        <geometry>
          <cylinder>
            <radius>0.0508</radius>
            <length>0.055</length>
          </cylinder>
        </geometry>
      </collision>

      <visual name="lidar_sensor_visual">
        <pose>-0.032 0 0.171 0 0 0</pose>
        <geometry>
          <mesh>
            <uri>model://turtlebot3_common/meshes/sensors/lds.stl</uri>
            <scale>0.001 0.001 0.001</scale>
          </mesh>
        </geometry>
        <material>
          <ambient>0.2 0.2 0.2 1.0</ambient>
          <diffuse>0.2 0.2 0.2 1.0</diffuse>
        </material>
      </visual>

      <sensor name="hls_lfcd_lds" type="gpu_lidar">
        <always_on>true</always_on>
        <visualize>true</visualize>
        <pose>-0.032 0 0.171 0 0 0</pose>
        <update_rate>5</update_rate>
        <topic>scan</topic>
        <gz_frame_id>base_scan</gz_frame_id>
        <lidar>
          <scan>
            <horizontal>
              <samples>360</samples>
              <resolution>1.000000</resolution>
              <min_angle>0.000000</min_angle>
              <max_angle>6.280000</max_angle>
            </horizontal>
          </scan>
          <range>
            <min>0.120000</min>
            <!-- 3.5 m = real TurtleBot3 Burger LDS-01 range. The earlier 12.0
                 was a sim hack to make slam_toolbox localize in the big world;
                 with the Oak-D + rtabmap visual loop closure we test at the
                 real range. Set back to 12.0 to reproduce the old behavior. -->
            <max>3.5</max>
            <resolution>0.015000</resolution>
          </range>
          <noise>
            <type>gaussian</type>
            <mean>0.0</mean>
            <stddev>0.01</stddev>
          </noise>
        </lidar>
      </sensor>
    </link>

    <!-- ================================================================
         Oak-D depth camera (forward-facing RGBD), emulating the unit
         mounted on the real Burger. Provides RGB + registered depth for
         RTAB-Map visual loop closure (see exploration_bringup/config/
         rtabmap.yaml). The LiDAR still builds the occupancy grid; depth
         is a localization aid only.

         Specs chosen to approximate the Oak-D:
           - horizontal_fov 1.204 rad (~69 deg)
           - clip 0.2 .. 12.0 m (Oak-D usable stereo depth)
           - 15 Hz (depth is expensive; on-robot we decimate further)

         Frame: gz_frame_id is the ROS optical frame name. The matching
         base_link -> oakd_rgb_optical_frame TF (with the REP-103 optical
         rotation) must be added to the burger URDF in the next step;
         until then RTAB-Map cannot consume these topics.
         ================================================================ -->
    <link name="oakd_camera_link">
      <inertial>
        <pose>0.045 0 0.130 0 0 0</pose>
        <inertia>
          <ixx>1e-05</ixx>
          <ixy>0</ixy>
          <ixz>0</ixz>
          <iyy>1e-05</iyy>
          <iyz>0</iyz>
          <izz>1e-05</izz>
        </inertia>
        <mass>0.06</mass>
      </inertial>

      <visual name="oakd_visual">
        <pose>0.045 0 0.130 0 0 0</pose>
        <geometry>
          <box>
            <!-- Oak-D enclosure ~ 91 x 28 x 17.5 mm (W x H x D) -->
            <size>0.018 0.091 0.025</size>
          </box>
        </geometry>
        <material>
          <ambient>0.1 0.1 0.1 1.0</ambient>
          <diffuse>0.1 0.1 0.1 1.0</diffuse>
        </material>
      </visual>

      <sensor name="oakd" type="rgbd_camera">
        <always_on>true</always_on>
        <visualize>true</visualize>
        <!-- Lightened for sim performance: 320x240 @ 10 Hz keeps RTF near 1.0
             so rgbd_sync stays fed (640x480 @ 15 Hz dropped RTF to ~0.6 and
             starved rtabmap). Plenty for rtabmap's 1 Hz loop-closure detection.
             The real Oak-D can run higher res on hardware. -->
        <update_rate>10</update_rate>
        <pose>0.045 0 0.130 0 0 0</pose>
        <topic>oakd</topic>
        <gz_frame_id>oakd_rgb_optical_frame</gz_frame_id>
        <camera name="oakd">
          <camera_info_topic>oakd/camera_info</camera_info_topic>
          <horizontal_fov>1.204</horizontal_fov>
          <image>
            <width>320</width>
            <height>240</height>
            <format>R8G8B8</format>
          </image>
          <clip>
            <near>0.2</near>
            <far>12.0</far>
          </clip>
          <depth_camera>
            <clip>
              <near>0.2</near>
              <far>12.0</far>
            </clip>
          </depth_camera>
          <noise>
            <type>gaussian</type>
            <mean>0.0</mean>
            <stddev>0.005</stddev>
          </noise>
        </camera>
      </sensor>
    </link>

    <link name="wheel_left_link">

      <inertial>
        <pose>0 0.08 0.023 -1.57 0 0</pose>
        <inertia>
          <ixx>5.445e-05</ixx>
          <ixy>0</ixy>
          <ixz>0</ixz>
          <iyy>5.445e-05</iyy>
          <iyz>0</iyz>
          <izz>1.089e-04</izz>
        </inertia>
        <mass>0.1</mass>
      </inertial>

      <collision name="wheel_left_collision">
        <pose>0 0.08 0.023 -1.57 0 0</pose>
        <geometry>
          <cylinder>
            <radius>0.033</radius>
            <length>0.018</length>
          </cylinder>
        </geometry>
        <surface>
          <!-- This friction pamareter don't contain reliable data!! -->
          <friction>
            <ode>
              <mu>100000.0</mu>
              <mu2>100000.0</mu2>
              <fdir1>0 0 0</fdir1>
              <slip1>0.0</slip1>
              <slip2>0.0</slip2>
            </ode>
          </friction>
          <contact>
            <ode>
              <soft_cfm>0</soft_cfm>
              <soft_erp>0.2</soft_erp>
              <kp>1e+5</kp>
              <kd>1</kd>
              <max_vel>0.01</max_vel>
              <min_depth>0.001</min_depth>
            </ode>
          </contact>
        </surface>
      </collision>

      <visual name="wheel_left_visual">
        <pose>0 0.08 0.023 0 0 0</pose>
        <geometry>
          <mesh>
            <uri>model://turtlebot3_common/meshes/wheels/left_tire.stl</uri>
            <scale>0.001 0.001 0.001</scale>
          </mesh>
        </geometry>
        <material>
          <ambient>0.2 0.2 0.2 1.0</ambient>
          <diffuse>0.2 0.2 0.2 1.0</diffuse>
        </material>
      </visual>
    </link>

    <link name="wheel_right_link">

      <inertial>
        <pose>0.0 -0.08 0.023 -1.57 0 0</pose>
        <inertia>
          <ixx>5.445e-05</ixx>
          <ixy>0</ixy>
          <ixz>0</ixz>
          <iyy>5.445e-05</iyy>
          <iyz>0</iyz>
          <izz>1.089e-04</izz>
        </inertia>
        <mass>0.1</mass>
      </inertial>

      <collision name="wheel_right_collision">
        <pose>0.0 -0.08 0.023 -1.57 0 0</pose>
        <geometry>
          <cylinder>
            <radius>0.033</radius>
            <length>0.018</length>
          </cylinder>
        </geometry>
        <surface>
          <!-- This friction pamareter don't contain reliable data!! -->
          <friction>
            <ode>
              <mu>100000.0</mu>
              <mu2>100000.0</mu2>
              <fdir1>0 0 0</fdir1>
              <slip1>0.0</slip1>
              <slip2>0.0</slip2>
            </ode>
          </friction>
          <contact>
            <ode>
              <soft_cfm>0</soft_cfm>
              <soft_erp>0.2</soft_erp>
              <kp>1e+5</kp>
              <kd>1</kd>
              <max_vel>0.01</max_vel>
              <min_depth>0.001</min_depth>
            </ode>
          </contact>
        </surface>
      </collision>

      <visual name="wheel_right_visual">
        <pose>0.0 -0.08 0.023 0 0 0</pose>
        <geometry>
          <mesh>
            <uri>model://turtlebot3_common/meshes/wheels/right_tire.stl</uri>
            <scale>0.001 0.001 0.001</scale>
          </mesh>
        </geometry>
        <material>
          <ambient>0.2 0.2 0.2 1.0</ambient>
          <diffuse>0.2 0.2 0.2 1.0</diffuse>
        </material>
      </visual>
    </link>

    <link name='caster_back_link'>
      <pose>-0.081 0 -0.004 -1.57 0 0</pose>
      <inertial>
        <mass>0.005</mass>
        <inertia>
          <ixx>0.00001</ixx>
          <ixy>0.000</ixy>
          <ixz>0.000</ixz>
          <iyy>0.00001</iyy>
          <iyz>0.000</iyz>
          <izz>0.00001</izz>
        </inertia>
      </inertial>
      <collision name='collision'>
        <geometry>
          <sphere>
            <radius>0.005000</radius>
          </sphere>
        </geometry>
        <surface>
          <contact>
            <ode>
              <soft_cfm>0</soft_cfm>
              <soft_erp>0.2</soft_erp>
              <kp>1e+5</kp>
              <kd>1</kd>
              <max_vel>0.01</max_vel>
              <min_depth>0.001</min_depth>
            </ode>
          </contact>
        </surface>
      </collision>
    </link>

    <joint name="base_joint" type="fixed">
      <parent>base_footprint</parent>
      <child>base_link</child>
      <pose>0.0 0.0 0.010 0 0 0</pose>
    </joint>

    <joint name="wheel_left_joint" type="revolute">
      <parent>base_link</parent>
      <child>wheel_left_link</child>
      <pose>0.0 0.08 0.023 -1.57 0 0</pose>
      <axis>
        <xyz>0 0 1</xyz>
        <limit>
          <effort>20</effort>
        </limit>
      </axis>
    </joint>

    <joint name="wheel_right_joint" type="revolute">
      <parent>base_link</parent>
      <child>wheel_right_link</child>
      <pose>0.0 -0.08 0.023 -1.57 0 0</pose>
      <axis>
        <xyz>0 0 1</xyz>
        <limit>
          <effort>20</effort>
        </limit>
      </axis>
    </joint>

    <joint name='caster_back_joint' type='ball'>
      <parent>base_link</parent>
      <child>caster_back_link</child>
    </joint>

    <joint name="imu_joint" type="fixed">
      <parent>base_link</parent>
      <child>imu_link</child>
      <pose>-0.032 0 0.068 0 0 0</pose>
      <axis>
        <xyz>0 0 1</xyz>
      </axis>
    </joint>

    <joint name="lidar_joint" type="fixed">
      <parent>base_link</parent>
      <child>base_scan</child>
      <pose>-0.032 0 0.171 0 0 0</pose>
      <axis>
        <xyz>0 0 1</xyz>
      </axis>
    </joint>

    <joint name="oakd_camera_joint" type="fixed">
      <parent>base_link</parent>
      <child>oakd_camera_link</child>
      <pose>0.045 0 0.130 0 0 0</pose>
      <axis>
        <xyz>0 0 1</xyz>
      </axis>
    </joint>

    <plugin filename="gz-sim-diff-drive-system" name="gz::sim::systems::DiffDrive">

      <!-- wheels -->
      <left_joint>wheel_left_joint</left_joint>
      <right_joint>wheel_right_joint</right_joint>

      <!-- kinematics -->
      <wheel_separation>0.160</wheel_separation>
      <wheel_radius>0.033</wheel_radius>

      <!-- limits -->
      <max_linear_acceleration>1.0</max_linear_acceleration>

      <topic>cmd_vel</topic>

      <odom_topic>odom</odom_topic>
      <frame_id>odom</frame_id>
      <child_frame_id>base_footprint</child_frame_id>
      <odom_publisher_frequency>30</odom_publisher_frequency>

      <tf_topic>/tf</tf_topic>

    </plugin>

    <plugin filename="gz-sim-joint-state-publisher-system" name="gz::sim::systems::JointStatePublisher">
      <topic>joint_states</topic>
      <joint_name>wheel_left_joint</joint_name>
      <joint_name>wheel_right_joint</joint_name>
    </plugin>

  </model>
</sdf>
